Workbook

Sheet Front Sheet
A1: AI Agent Business Case
A2: Front Sheet
A3: Confidential - Do not distribute
B5: Agent Details
C7: Item | E7: Description
C8: Agent Name | E8: My Meetings Twin
C9: Agent Description | E9: The My Meetings Twin Agent supports governance meeting preparation by guiding users through structured workflows for KPI tracking, DIA data capture, and meeting readiness activities. It is a Copilot Studio Agent that utilizes AI and Agent Flows to automate and accelerate work.
C10: Process / Use Case Area | E10: GSC
C11: Business Area / Function | E11: GSC
C12: Process Owner | E12: Sumit Kaura
C13: AI / Agent Owner | E13: Vinciane Polet
C14: Value Score | E14: ='Business Case My Meeting Twin'!I27 -> 3.75
C15: Agent Complexity | E15: ='Business Case My Meeting Twin'!I42 -> High

Sheet Settings
A1: AI AGENT BUSINESS CASE - SETTINGS
A2: Settings
A3: Confidential - Do not distribute
B5: Working Time Constants
C7: # | D7: Option | E7: Value | G7: Notes
C8: 1 | D8: Working hours per day | G8: hours
C9: 2 | D9: Working days per week | G9: days
C10: 3 | D10: Working days per year | G10: days
C11: 4 | D11: Working hours per year | E11: =37.5*47 -> 1762.5 | G11: hours
C12: 5 | D12: Avg fully loaded cost per FTE (annual) | E12: 100000 | G12: Currency from Define sheet
B15: Agent Complexity Scoring
C17: Level | D17: Score Range | E17: Dev Effort (weeks) | F17: Typical Cost | G17: Description
C18: Low | D18: 1.0 – 1.8 | E18: 2 – 4 | F18: 15000 | G18: Single tool, structured I/O, minimal reasoning
C19: Medium | D19: 1.81 – 2.5 | E19: 5 – 10 | F19: 40000 | G19: Multi-tool, some judgment, human-in-the-loop
C20: High | D20: 2.51 – 3.0 | E20: 11 – 20 | F20: 80000 | G20: Multi-step reasoning, autonomy, orchestration
B23: Dropdown Values for Complexity Questions
C25: Abbreviation | D25: Question | E25: Low (1) | F25: Medium (2) | G25: High (3)
C26: tools | D26: Number of tools/systems | E26: 1 – 2 | F26: 3 – 5 | G26: 6+
C27: data | D27: Data sources & types | E27: 1 structured | F27: 2-3 mixed | G27: 4+ unstructured
C28: reason | D28: Reasoning complexity | E28: Rule-based | F28: Some judgment | G28: Complex reasoning
C29: auton | D29: Level of autonomy | E29: Fully supervised | F29: Human-in-the-loop | G29: Autonomous decisions
C30: escal | D30: Exception handling | E30: Simple escalation | F30: Defined fallbacks | G30: Self-recovery needed
C31: integr | D31: Integration depth | E31: Read-only / API | F31: Read-write API | G31: Deep system integration
C32: regul | D32: Regulatory / compliance | E32: None | F32: Some oversight needed | G32: Highly regulated
C33: outvar | D33: Output variability | E33: Deterministic | F33: Semi-variable | G33: Highly variable / creative
B36: Complexity Weights
C38: # | D38: Dimension | E38: Weight
C39: 1 | D39: Number of tools/systems | E39: 0.15
C40: 2 | D40: Data sources & types | E40: 0.15
C41: 3 | D41: Reasoning complexity | E41: 0.2
C42: 4 | D42: Level of autonomy | E42: 0.15
C43: 5 | D43: Exception handling | E43: 0.1
C44: 6 | D44: Integration depth | E44: 0.1
C45: 7 | D45: Regulatory / compliance | E45: 0.05
C46: 8 | D46: Output variability | E46: 0.1
D47: Total | E47: =SUM(E39:E46) -> 1
B50: P&L Impact Categories
C52: # | D52: Category | E52: Type | F52: Description
C53: 1 | D53: Labour cost savings | E53: Cost Reduction | F53: FTEs freed up × fully loaded cost
C54: 2 | D54: Error / rework reduction | E54: Cost Reduction | F54: Reduction in cost of quality failures
...

Sheet Business Case My Meeting Twin
A1: AI Agent Business Case
A2: Value Score – ROI – P&L Impact
A3: Confidential - Do not distribute
B5: Step 1: Productivity Impact
I6: Facilitated meeting | Q6: DIA | X6: Meeting duration | AE6: Meeting skipped
D7: # | E7: Question | F7: Guidance | G7: Your Answer | I7: FTEs Freed Up | L7: # | M7: Question | N7: Guidance | O7: Your Answer | Q7: FTEs Freed Up | S7: # | T7: Question | U7: Guidance | V7: Your Answer | X7: FTEs Freed Up | Z7: # | AA7: Question | AB7: Guidance | AC7: Your Answer | AE7: FTEs Freed Up
D8: 1.1 | E8: % of task the agent can automate | F8: What share of the work can the agent handle end-to-end? (0-100%) | G8: =30% -> 0.3 | I8: =IFERROR(($G$8*$G$9*$G$11*IF($G$10="Daily",260,IF($G$10="Weekly",52,IF($G$10="Monthly",12,1))))/Settings!$E$11,0) -> 98.532 | L8: 1.1 | M8: % of task the agent can automate | N8: What share of the work can the agent handle end-to-end? (0-100%) | O8: =30% -> 0.3 | Q8: =IFERROR((O8*O9*O11*IF(O10="Daily",260,IF(O10="Weekly",52,IF(O10="Monthly",12,1))))/Settings!$E$11,0) -> 28.7776 | S8: 1.1 | T8: % of task the agent can automate | U8: What share of the work can the agent handle end-to-end? (0-100%) | V8: =16.67% -> 0.1667 | X8: =IFERROR((V8*V9*V11*IF(V10="Daily",260,IF(V10="Weekly",52,IF(V10="Monthly",12,1))))/Settings!$E$11,0) -> 176.79052 | Z8: 1.1 | AA8: % of task the agent can automate | AB8: What share of the work can the agent handle end-to-end? (0-100%) | AC8: =100% -> 1 | AE8: =IFERROR((AC8*AC9*AC11*IF(AC10="Daily",260,IF(AC10="Weekly",52,IF(AC10="Monthly",12,1))))/Settings!$E$11,0) -> 47.215422
D9: 1.2 | E9: Number of process runs | F9: How many times is this task executed per frequency period? | G9: =0.9*9200*47*85% -> 330786 | I9: Annual Hours Saved | L9: 1.2 | M9: Number of process runs | N9: How many times is this task executed per frequency period? | O9: =0.46*9200*47*85% -> 169068.4 | Q9: Annual Hours Saved | S9: 1.2 | T9: Number of process runs | U9: How many times is this task executed per frequency period? | V9: =5.84*9200*47*85% -> 2146433.6 | X9: Annual Hours Saved | Z9: 1.2 | AA9: Number of process runs | AB9: How many times is this task executed per frequency period? | AC9: =0.26*9200*47*85% -> 95560.4 | AE9: Annual Hours Saved
D10: 1.3 | E10: Frequency of process runs | F10: Daily / Weekly / Monthly / Yearly | G10: Yearly | I10: =IFERROR($G$8*$G$9*$G$11*IF($G$10="Daily",260,IF($G$10="Weekly",52,IF($G$10="Monthly",12,1))),0) -> 173662.65 | L10: 1.3 | M10: Frequency of process runs | N10: Daily / Weekly / Monthly / Yearly | O10: Yearly | Q10: =IFERROR(O8*O9*O11*IF(O10="Daily",260,IF(O10="Weekly",52,IF(O10="Monthly",12,1))),0) -> 50720.52 | S10: 1.3 | T10: Frequency of process runs | U10: Daily / Weekly / Monthly / Yearly | V10: Yearly | X10: =IFERROR(V8*V9*V11*IF(V10="Daily",260,IF(V10="Weekly",52,IF(V10="Monthly",12,1))),0) -> 311593.29 | Z10: 1.3 | AA10: Frequency of process runs | AB10: Daily / Weekly / Monthly / Yearly | AC10: Yearly | AE10: =IFERROR(AC8*AC9*AC11*IF(AC10="Daily",260,IF(AC10="Weekly",52,IF(AC10="Monthly",12,1))),0) -> 83217.182
D11: 1.4 | E11: Manual effort per run (hours) | F11: How long does one run take a human today? | G11: =1+0.75 -> 1.75 | I11: Labour Cost Saved (annual) | L11: 1.4 | M11: Manual effort per run (hours) | N11: How long does one run take a human today? | O11: 1 | Q11: Labour Cost Saved (annual) | S11: 1.4 | T11: Manual effort per run (hours) | U11: How long does one run take a human today? | V11: =52.25/60 -> 0.87083333 | X11: Labour Cost Saved (annual) | Z11: 1.4 | AA11: Manual effort per run (hours) | AB11: How long does one run take a human today? | AC11: =52.25/60 -> 0.87083333 | AE11: Labour Cost Saved (annual)
I12: =IFERROR($I$8*Settings!$E$12,0) -> 9853200 | Q12: =IFERROR(Q8*Settings!$E$12,0) -> 2877760 | X12: =IFERROR(X8*Settings!$E$12,0) -> 17679052 | AE12: =IFERROR(AE8*Settings!$E$12,0) -> 4721542.2
B14: Step 2: P&L Impact (beyond productivity)
D16: # | E16: P&L Category | F16: Guidance | G16: Annual Estimate | I16: Total P&L Impact
D17: 2.1 | E17: Error / rework cost reduction | F17: How much do errors, rework or quality failures cost annually today? What % could the agent reduce? | G17: 0 | I17: =SUM(G17:G21)+I12+Q12+X12+AE12 -> 35131554
D18: 2.2 | E18: Faster cycle time value | F18: Revenue pulled forward or opportunity cost from delays? Annual estimate. | G18: 0
D19: 2.3 | E19: Revenue uplift enabled | F19: Any new revenue the agent directly enables (e.g. faster quotes, more leads processed)? | G19: 0
D20: 2.4 | E20: Compliance risk avoided | F20: Potential fines, audit costs, or remediation costs avoided annually? | G20: 0
D21: 2.5 | E21: Other savings / value | F21: Any other quantifiable value (e.g. reduced vendor costs, license savings)? | G21: 0
B24: Step 3: Business Value Priorities (rate 0-5)
D26: # | E26: Priority | F26: Guidance | G26: Score (0-5) | I26: Value Score
D27: 3.1 | E27: Save Manual Effort | F27: Redeploy employees to more meaningful tasks | G27: 4 | I27: =IFERROR(AVERAGE(G27:G34),0) -> 3.75
D28: 3.2 | E28: Error Reduction | F28: Improve quality by reducing errors | G28: 4
D29: 3.3 | E29: Speed / Efficiency | F29: Reduce process cycle time | G29: 4
D30: 3.4 | E30: Scalability | F30: Handle volume growth without adding headcount | G30: 4
D31: 3.5 | E31: Customer / Stakeholder Experience | F31: Improve response time, quality, satisfaction | G31: 4
D32: 3.6 | E32: Regulatory Compliance | F32: Adhere to regulatory or audit requirements | G32: 0
D33: 3.7 | E33: Data-Driven Decisions | F33: Enable better insights from data the agent processes | G33: 5
D34: 3.8 | E34: Employee Experience | F34: Remove tedious work, improve morale | G34: 5
B36: Step 4: Agent Complexity Assessment
I37: =I27 -> 3.75
D38: # | E38: Dimension | F38: Guidance | G38: Select: Low / Medium / High | I38: Estimated Dev Effort
D39: 4.1 | E39: Number of tools / systems | F39: How many apps, APIs or systems does the agent interact with? | G39: High | I39: =IFERROR(IF(G57<=1.8,"2 – 4 weeks",IF(G57<=2.5,"5 – 10 weeks","11 – 20 weeks")),"—") -> 11 – 20 weeks
D40: 4.2 | E40: Data sources & types | F40: How many data sources? Structured (tables) vs unstructured (emails, PDFs)? | G40: High
D41: 4.3 | E41: Reasoning complexity | F41: Does the agent follow fixed rules, or need judgment and interpretation? | G41: High | I41: Overall Complexity
D42: 4.4 | E42: Level of autonomy | F42: Can a human review every output, or must the agent act independently? | G42: High | I42: =IFERROR(IF(G57<=1.8,"Low",IF(G57<=2.5,"Medium","High")),"—") -> High
D43: 4.5 | E43: Exception handling | F43: What happens when the agent encounters something unexpected? | G43: Low
D44: 4.6 | E44: Integration depth | F44: Read-only queries, or does the agent write back / trigger actions in systems? | G44: High | I44: Estimated Cost
D45: 4.7 | E45: Regulatory / compliance needs | F45: Is the process subject to regulatory oversight or audit trails? | G45: Medium | I45: =IFERROR(IF(G57<=1.8,15000,IF(G57<=2.5,40000,80000)),0) -> 80000
D46: 4.8 | E46: Output variability | F46: Are outputs deterministic (same input → same output) or creative / variable? | G46: High
D48: Calculations
...
